Workbook

Sheet 개요
A1: AI 지역관광 맞춤 여행플래너(전통시장 특화) — 2주 프로젝트 개요
A2: 팀 4인(PM·UX·백엔드·프론트) 기준 타임테이블. 독거노인_AI안부_2주_타임테이블 양식을 참고해 재구성
A4: 프로젝트명 | B4: AI 기반 지역 관광 맞춤 여행 플래너 (전통시장·5일장 차별화)
A5: 기간 | B5: 2026-07-06 ~ 2026-07-17 (2주, 주말 제외 10 영업일)
A6: 오늘 기준 | B6: 7/9 (Day4) — 내일(7/10)부터 실제 개발 착수, 잔여 개발일 6일(7/10, 7/13~7/17)
A7: 팀 구성 | B7: PM 1, UX 1, 백엔드(AI 포함) 1, 프론트엔드 1 — 총 4인
A8: 우선순위 방식 | B8: MoSCoW (Must 16 / Should 7 / Could 7 / 총 30개 항목, 8.우선순위MoSCoW 시트 기준)
A9: 핵심 기능(Must) | B9: 로그인/회원가입, 자연어 조건입력·추출, RAG 후보검색, 결과화면, 일정수정, 리뷰요약·작성·조회, 상인대시보드, 관리자 화면/대시보드, 전통시장 정보관리, 즐겨찾기, 예약(결제 제외)
A10: 추후 고도화(Should~Could) | B10: QR 방문인증·개선사항 관리, 상인 할인·이벤트·쿠폰, QR 미니 홈페이지, 5일장 정보/장날 연동, 시장 내부지도·동선추천, 5일장 구역체크인, 관리자 공지사항/문의관리
A11: Phase 2~3(로드맵) | B11: 예약 선결제, 시장 혼잡도 안내, AI 스탬프 투어·리워드 관리
A12: 산출물 | B12: PRD(16개 시트), Streamlit/Gradio MVP, 발표자료, 데모 리허설
A13: 발표일 | B13: 2026-07-17 (Day10) 오전 최종 리허설 → 발표

Sheet 체크리스트
A1: 태스크 체크리스트 (선행조건·진행 상태) — AI 지역관광 여행플래너 (전통시장 특화) 2주 프로젝트
A2: '선행'=이 태스크 시작 전에 끝나 있어야 하는 태스크 ID. 상태 칸에 '완료' 입력 시 하단 진행률 자동 계산 / 팀원 4인(PM·UX·백엔드·프론트), 오늘은 7/9(Day4), 내일부터 개발 시작해 잔여 개발일 6일(7/10,13~17)
A4: ID | B4: 일자 | C4: 담당 | D4: 태스크 | E4: 선행조건 | F4: 상태 | G4: 비고
A5: T1 | B5: 7/6 | C5: 전원 | D5: 킥오프 — 목표·범위·공통데이터 합의 | E5: - | F5: 완료
A6: T2 | B6: 7/6 | C6: PM | D6: 공공데이터·지도 API 신청/승인 요청 | E6: T1 | F6: 완료
A7: T3 | B7: 7/6 | C7: UX | D7: 페르소나 3종 초안(가족/친구/커플) | E7: T1 | F7: 완료
A8: T4 | B8: 7/6 | C8: 백엔드 | D8: LLM API·개발환경(Colab/Streamlit) 세팅 | E8: T1 | F8: 완료
A9: T5 | B9: 7/6 | C9: 백엔드 | D9: 관광 공공데이터 CSV 다운로드 착수 | E9: T2 | F9: 완료
A10: T6 | B10: 7/6 | C10: 프론트 | D10: Gradio/Streamlit 세팅·UI 레퍼런스 조사 | E10: T1 | F10: 완료
A11: T7 | B11: 7/7 | C11: PM | D11: 문제정의서·핵심 시나리오 정의 | E11: T1 | F11: 완료
A12: T8 | B12: 7/7 | C12: UX | D12: 저니맵(가족/친구/커플) 작성 | E12: T3,T7 | F12: 완료
A13: T9 | B13: 7/7 | C13: UX | D13: 대화 스크립트(챗봇 시나리오) 초안 | E13: T8 | F13: 완료
A14: T10 | B14: 7/7 | C14: 백엔드 | D14: 조건 슬롯 추출 프롬프트 v0 | E14: T5 | F14: 완료
A15: T11 | B15: 7/7 | C15: 백엔드 | D15: RAG 벡터 인덱스(FAISS) 초안 구축 | E15: T10 | F15: 완료
A16: T12 | B16: 7/7 | C16: 프론트 | D16: 화면구조(IA) 설계 — 4대 메인화면 6/4/4/8탭 | E16: T6 | F16: 완료
... A21: T17 | B21: 7/9 | C21: 프론트 | D21: 로그인/회원가입 화면 구현 | E21: T15,T16 | F21: 진행
A22: T18 | B22: 7/9 | C22: PM | D22: 전통시장·5일장 차별화 요구사항 확정(FR-057~078), MoSCoW 재정렬 | E22: T14 | F22: 진행 | G22: Must 16 / Should 7 / Could 7로 확정
A23: T19 | B23: 7/9 | C23: UX | D23: 전통시장 방문 니즈 페르소나 반영, 신규 화면 정의(SC-16~26) | E23: T18 | F23: 진행
A24: T20 | B24: 7/9 | C24: 백엔드 | D24: RAG 후보검색·코스생성 로직 고도화 | E24: T11 | F24: 진행
A25: T21 | B25: 7/10 | C25: 백엔드 | D25: 자연어 조건입력/추출 API 완성 | E25: T16,T20 | F25: 대기 | G25: 개발 첫날
A26: T22 | B26: 7/10 | C26: 백엔드 | D26: 대화 세션 저장/이어서 하기 구현 | E26: T21 | F26: 대기
A27: T23 | B27: 7/10 | C27: 프론트 | D27: 대화 UI + 대화기록 사이드바 구현 | E27: T21,T22 | F27: 대기
A28: T24 | B28: 7/10 | C28: 백엔드 | D28: 즐겨찾기(찜하기) API 구현(FR-059) | E28: T16 | F28: 대기
A29: T25 | B29: 7/13 | C29: 프론트 | D29: RAG 후보검색 결과화면·장소카드 구현 | E29: T20,T21 | F29: 대기
A30: T26 | B30: 7/13 | C30: 백엔드 | D30: 일정 수정(추가·삭제·교체) API(FR-029~034) | E30: T20 | F30: 대기
A31: T27 | B31: 7/13 | C31: 프론트 | D31: 일정 수정 UI 구현 | E31: T26 | F31: 대기
A32: T28 | B32: 7/13 | C32: 백엔드 | D32: 리뷰 요약 로직(FR-035) | E32: T20 | F32: 대기
A33: T29 | B33: 7/14 | C33: 백엔드 | D33: 리뷰 작성/조회 API(FR-038~040) | E33: T16 | F33: 대기
A34: T30 | B34: 7/14 | C34: 프론트 | D34: 리뷰 화면 구현 | E34: T29 | F34: 대기
A35: T31 | B35: 7/14 | C35: 백엔드 | D35: 상인 대시보드 API(FR-048~049) | E35: T16 | F35: 대기
A36: T32 | B36: 7/14 | C36: 프론트 | D36: 상인 대시보드 화면 구현 | E36: T31 | F36: 대기
A37: T33 | B37: 7/14 | C37: 백엔드/프론트 | D37: 전통시장 예약주문 접수/확인(FR-063~064, 결제 제외) | E37: T16,T31 | F37: 대기 | G37: Should→Must 승격분, 일정 압박 주의
A38: T34 | B38: 7/15 | C38: 백엔드 | D38: 전통시장 정보관리(관리자) API(FR-060) | E38: T16 | F38: 대기
A39: T35 | B39: 7/15 | C39: 프론트 | D39: 관리자 화면(8탭) 구현 | E39: T34 | F39: 대기
A40: T36 | B40: 7/15 | C40: 백엔드 | D40: RBAC 권한 처리(FR-050) | E40: T34 | F40: 대기
A41: T37 | B41: 7/16 | C41: PM | D41: 관리자 대시보드/DB현황 지표 정의 | E41: T34 | F41: 대기
A42: T38 | B42: 7/16 | C42: 백엔드 | D42: 관리자 대시보드 API(FR-054~055) | E42: T37 | F42: 대기
A43: T39 | B43: 7/16 | C43: 프론트 | D43: 관리자 대시보드 화면 구현 | E43: T38 | F43: 대기
A44: T40 | B44: 7/16 | C44: 전원 | D44: 전체 기능 통합 테스트(Must 16개 항목 전수 점검) | E44: T17~T39 | F44: 대기 | G44: Must 16개 전수 체크
A45: T41 | B45: 7/17 | C45: 전원 | D45: 버그 수정·최종 점검 | E45: T40 | F45: 대기
...

Sheet 간트차트
A1: 간트차트 — 태스크별 일정 (담당자 색상 기준)
A2: 보라=PM · 주황=UX · 파랑=백엔드 · 초록=프론트 · 청록=백엔드+프론트 · 회색=전원 / 각 태스크의 배정일에 담당자 색상 표시
A4: ID | B4: 담당 | C4: 태스크 | D4: 7/6 | E4: 7/7 | F4: 7/8 | G4: 7/9 | H4: 7/10 | I4: 7/13 | J4: 7/14 | K4: 7/15 | L4: 7/16 | M4: 7/17
A5: T1 | B5: 전원 | C5: 킥오프 — 목표·범위·공통데이터 합의 | D5: ALL
A6: T2 | B6: PM | C6: 공공데이터·지도 API 신청/승인 요청 | D6: PM
A7: T3 | B7: UX | C7: 페르소나 3종 초안(가족/친구/커플) | D7: UX
A8: T4 | B8: 백엔드 | C8: LLM API·개발환경(Colab/Streamlit) 세팅 | D8: BE
A9: T5 | B9: 백엔드 | C9: 관광 공공데이터 CSV 다운로드 착수 | D9: BE
A10: T6 | B10: 프론트 | C10: Gradio/Streamlit 세팅·UI 레퍼런스 조사 | D10: FE
A11: T7 | B11: PM | C11: 문제정의서·핵심 시나리오 정의 | E11: PM
A12: T8 | B12: UX | C12: 저니맵(가족/친구/커플) 작성 | E12: UX
A13: T9 | B13: UX | C13: 대화 스크립트(챗봇 시나리오) 초안 | E13: UX
A14: T10 | B14: 백엔드 | C14: 조건 슬롯 추출 프롬프트 v0 | E14: BE
A15: T11 | B15: 백엔드 | C15: RAG 벡터 인덱스(FAISS) 초안 구축 | E15: BE
A16: T12 | B16: 프론트 | C16: 화면구조(IA) 설계 — 4대 메인화면 6/4/4/8탭 | E16: FE
A17: T13 | B17: 프론트 | C17: 메인 화면(6탭) 목업 제작 | F17: FE
A18: T14 | B18: PM | C18: PRD 작성(기능요구사항 v1.0~v1.4) 및 확정 | F18: PM
A19: T15 | B19: UX | C19: 톤앤매너·와이어프레임(로그인~관리자) | F19: UX
A20: T16 | B20: 백엔드 | C20: 로그인/회원가입 API 구현(FR-001~011) | F20: BE
A21: T17 | B21: 프론트 | C21: 로그인/회원가입 화면 구현 | G21: FE
A22: T18 | B22: PM | C22: 전통시장·5일장 차별화 요구사항 확정(FR-057~078), MoSCoW 재정렬 | G22: PM
A23: T19 | B23: UX | C23: 전통시장 방문 니즈 페르소나 반영, 신규 화면 정의(SC-16~26) | G23: UX
A24: T20 | B24: 백엔드 | C24: RAG 후보검색·코스생성 로직 고도화 | G24: BE
A25: T21 | B25: 백엔드 | C25: 자연어 조건입력/추출 API 완성 | H25: BE
A26: T22 | B26: 백엔드 | C26: 대화 세션 저장/이어서 하기 구현 | H26: BE
A27: T23 | B27: 프론트 | C27: 대화 UI + 대화기록 사이드바 구현 | H27: FE
A28: T24 | B28: 백엔드 | C28: 즐겨찾기(찜하기) API 구현(FR-059) | H28: BE
A29: T25 | B29: 프론트 | C29: RAG 후보검색 결과화면·장소카드 구현 | I29: FE
A30: T26 | B30: 백엔드 | C30: 일정 수정(추가·삭제·교체) API(FR-029~034) | I30: BE
A31: T27 | B31: 프론트 | C31: 일정 수정 UI 구현 | I31: FE
A32: T28 | B32: 백엔드 | C32: 리뷰 요약 로직(FR-035) | I32: BE
A33: T29 | B33: 백엔드 | C33: 리뷰 작성/조회 API(FR-038~040) | J33: BE
A34: T30 | B34: 프론트 | C34: 리뷰 화면 구현 | J34: FE
A35: T31 | B35: 백엔드 | C35: 상인 대시보드 API(FR-048~049) | J35: BE
A36: T32 | B36: 프론트 | C36: 상인 대시보드 화면 구현 | J36: FE
A37: T33 | B37: 백엔드/프론트 | C37: 전통시장 예약주문 접수/확인(FR-063~064, 결제 제외) | J37: BE·FE
A38: T34 | B38: 백엔드 | C38: 전통시장 정보관리(관리자) API(FR-060) | K38: BE
A39: T35 | B39: 프론트 | C39: 관리자 화면(8탭) 구현 | K39: FE
A40: T36 | B40: 백엔드 | C40: RBAC 권한 처리(FR-050) | K40: BE
A41: T37 | B41: PM | C41: 관리자 대시보드/DB현황 지표 정의 | L41: PM
...

Sheet 동적간트
A1: 동적 간트차트 — 체크리스트 상태와 실시간 연동
A2: 담당/상태는 '체크리스트' 탭 값을 실시간으로 불러옵니다(체크리스트에서 상태를 바꾸면 이 표도 자동 갱신). 파랑=완료 · 초록=진행 · 회색=대기 / 노란 배경 열=오늘(TODAY 기준 자동 이동)
A4: ID | B4: 태스크 | C4: 담당 | D4: 상태 | E4: 7/6 | F4: 7/7 | G4: 7/8 | H4: 7/9 | I4: 7/10 | J4: 7/13 | K4: 7/14 | L4: 7/15 | M4: 7/16 | N4: 7/17
A5: ='체크리스트'!A5 -> T1 | B5: ='체크리스트'!D5 -> 킥오프 — 목표·범위·공통데이터 합의 | C5: ='체크리스트'!C5 -> 전원 | D5: ='체크리스트'!F5 -> 완료 | E5: =IF(TEXT(E$4,"m/d")='체크리스트'!B5,1,"") -> 1 | F5: =IF(TEXT(F$4,"m/d")='체크리스트'!B5,1,"") | G5: =IF(TEXT(G$4,"m/d")='체크리스트'!B5,1,"") | H5: =IF(TEXT(H$4,"m/d")='체크리스트'!B5,1,"") | I5: =IF(TEXT(I$4,"m/d")='체크리스트'!B5,1,"") | J5: =IF(TEXT(J$4,"m/d")='체크리스트'!B5,1,"") | K5: =IF(TEXT(K$4,"m/d")='체크리스트'!B5,1,"") | L5: =IF(TEXT(L$4,"m/d")='체크리스트'!B5,1,"") | M5: =IF(TEXT(M$4,"m/d")='체크리스트'!B5,1,"") | N5: =IF(TEXT(N$4,"m/d")='체크리스트'!B5,1,"")
A6: ='체크리스트'!A6 -> T2 | B6: ='체크리스트'!D6 -> 공공데이터·지도 API 신청/승인 요청 | C6: ='체크리스트'!C6 -> PM | D6: ='체크리스트'!F6 -> 완료 | E6: =IF(TEXT(E$4,"m/d")='체크리스트'!B6,1,"") -> 1 | F6: =IF(TEXT(F$4,"m/d")='체크리스트'!B6,1,"") | G6: =IF(TEXT(G$4,"m/d")='체크리스트'!B6,1,"") | H6: =IF(TEXT(H$4,"m/d")='체크리스트'!B6,1,"") | I6: =IF(TEXT(I$4,"m/d")='체크리스트'!B6,1,"") | J6: =IF(TEXT(J$4,"m/d")='체크리스트'!B6,1,"") | K6: =IF(TEXT(K$4,"m/d")='체크리스트'!B6,1,"") | L6: =IF(TEXT(L$4,"m/d")='체크리스트'!B6,1,"") | M6: =IF(TEXT(M$4,"m/d")='체크리스트'!B6,1,"") | N6: =IF(TEXT(N$4,"m/d")='체크리스트'!B6,1,"")
A7: ='체크리스트'!A7 -> T3 | B7: ='체크리스트'!D7 -> 페르소나 3종 초안(가족/친구/커플) | C7: ='체크리스트'!C7 -> UX | D7: ='체크리스트'!F7 -> 완료 | E7: =IF(TEXT(E$4,"m/d")='체크리스트'!B7,1,"") -> 1 | F7: =IF(TEXT(F$4,"m/d")='체크리스트'!B7,1,"") | G7: =IF(TEXT(G$4,"m/d")='체크리스트'!B7,1,"") | H7: =IF(TEXT(H$4,"m/d")='체크리스트'!B7,1,"") | I7: =IF(TEXT(I$4,"m/d")='체크리스트'!B7,1,"") | J7: =IF(TEXT(J$4,"m/d")='체크리스트'!B7,1,"") | K7: =IF(TEXT(K$4,"m/d")='체크리스트'!B7,1,"") | L7: =IF(TEXT(L$4,"m/d")='체크리스트'!B7,1,"") | M7: =IF(TEXT(M$4,"m/d")='체크리스트'!B7,1,"") | N7: =IF(TEXT(N$4,"m/d")='체크리스트'!B7,1,"")
A8: ='체크리스트'!A8 -> T4 | B8: ='체크리스트'!D8 -> LLM API·개발환경(Colab/Streamlit) 세팅 | C8: ='체크리스트'!C8 -> 백엔드 | D8: ='체크리스트'!F8 -> 완료 | E8: =IF(TEXT(E$4,"m/d")='체크리스트'!B8,1,"") -> 1 | F8: =IF(TEXT(F$4,"m/d")='체크리스트'!B8,1,"") | G8: =IF(TEXT(G$4,"m/d")='체크리스트'!B8,1,"") | H8: =IF(TEXT(H$4,"m/d")='체크리스트'!B8,1,"") | I8: =IF(TEXT(I$4,"m/d")='체크리스트'!B8,1,"") | J8: =IF(TEXT(J$4,"m/d")='체크리스트'!B8,1,"") | K8: =IF(TEXT(K$4,"m/d")='체크리스트'!B8,1,"") | L8: =IF(TEXT(L$4,"m/d")='체크리스트'!B8,1,"") | M8: =IF(TEXT(M$4,"m/d")='체크리스트'!B8,1,"") | N8: =IF(TEXT(N$4,"m/d")='체크리스트'!B8,1,"")
A9: ='체크리스트'!A9 -> T5 | B9: ='체크리스트'!D9 -> 관광 공공데이터 CSV 다운로드 착수 | C9: ='체크리스트'!C9 -> 백엔드 | D9: ='체크리스트'!F9 -> 완료 | E9: =IF(TEXT(E$4,"m/d")='체크리스트'!B9,1,"") -> 1 | F9: =IF(TEXT(F$4,"m/d")='체크리스트'!B9,1,"") | G9: =IF(TEXT(G$4,"m/d")='체크리스트'!B9,1,"") | H9: =IF(TEXT(H$4,"m/d")='체크리스트'!B9,1,"") | I9: =IF(TEXT(I$4,"m/d")='체크리스트'!B9,1,"") | J9: =IF(TEXT(J$4,"m/d")='체크리스트'!B9,1,"") | K9: =IF(TEXT(K$4,"m/d")='체크리스트'!B9,1,"") | L9: =IF(TEXT(L$4,"m/d")='체크리스트'!B9,1,"") | M9: =IF(TEXT(M$4,"m/d")='체크리스트'!B9,1,"") | N9: =IF(TEXT(N$4,"m/d")='체크리스트'!B9,1,"")
A10: ='체크리스트'!A10 -> T6 | B10: ='체크리스트'!D10 -> Gradio/Streamlit 세팅·UI 레퍼런스 조사 | C10: ='체크리스트'!C10 -> 프론트 | D10: ='체크리스트'!F10 -> 완료 | E10: =IF(TEXT(E$4,"m/d")='체크리스트'!B10,1,"") -> 1 | F10: =IF(TEXT(F$4,"m/d")='체크리스트'!B10,1,"") | G10: =IF(TEXT(G$4,"m/d")='체크리스트'!B10,1,"") | H10: =IF(TEXT(H$4,"m/d")='체크리스트'!B10,1,"") | I10: =IF(TEXT(I$4,"m/d")='체크리스트'!B10,1,"") | J10: =IF(TEXT(J$4,"m/d")='체크리스트'!B10,1,"") | K10: =IF(TEXT(K$4,"m/d")='체크리스트'!B10,1,"") | L10: =IF(TEXT(L$4,"m/d")='체크리스트'!B10,1,"") | M10: =IF(TEXT(M$4,"m/d")='체크리스트'!B10,1,"") | N10: =IF(TEXT(N$4,"m/d")='체크리스트'!B10,1,"")
A11: ='체크리스트'!A11 -> T7 | B11: ='체크리스트'!D11 -> 문제정의서·핵심 시나리오 정의 | C11: ='체크리스트'!C11 -> PM | D11: ='체크리스트'!F11 -> 완료 | E11: =IF(TEXT(E$4,"m/d")='체크리스트'!B11,1,"") | F11: =IF(TEXT(F$4,"m/d")='체크리스트'!B11,1,"") -> 1 | G11: =IF(TEXT(G$4,"m/d")='체크리스트'!B11,1,"") | H11: =IF(TEXT(H$4,"m/d")='체크리스트'!B11,1,"") | I11: =IF(TEXT(I$4,"m/d")='체크리스트'!B11,1,"") | J11: =IF(TEXT(J$4,"m/d")='체크리스트'!B11,1,"") | K11: =IF(TEXT(K$4,"m/d")='체크리스트'!B11,1,"") | L11: =IF(TEXT(L$4,"m/d")='체크리스트'!B11,1,"") | M11: =IF(TEXT(M$4,"m/d")='체크리스트'!B11,1,"") | N11: =IF(TEXT(N$4,"m/d")='체크리스트'!B11,1,"")
A12: ='체크리스트'!A12 -> T8 | B12: ='체크리스트'!D12 -> 저니맵(가족/친구/커플) 작성 | C12: ='체크리스트'!C12 -> UX | D12: ='체크리스트'!F12 -> 완료 | E12: =IF(TEXT(E$4,"m/d")='체크리스트'!B12,1,"") | F12: =IF(TEXT(F$4,"m/d")='체크리스트'!B12,1,"") -> 1 | G12: =IF(TEXT(G$4,"m/d")='체크리스트'!B12,1,"") | H12: =IF(TEXT(H$4,"m/d")='체크리스트'!B12,1,"") | I12: =IF(TEXT(I$4,"m/d")='체크리스트'!B12,1,"") | J12: =IF(TEXT(J$4,"m/d")='체크리스트'!B12,1,"") | K12: =IF(TEXT(K$4,"m/d")='체크리스트'!B12,1,"") | L12: =IF(TEXT(L$4,"m/d")='체크리스트'!B12,1,"") | M12: =IF(TEXT(M$4,"m/d")='체크리스트'!B12,1,"") | N12: =IF(TEXT(N$4,"m/d")='체크리스트'!B12,1,"")
A13: ='체크리스트'!A13 -> T9 | B13: ='체크리스트'!D13 -> 대화 스크립트(챗봇 시나리오) 초안 | C13: ='체크리스트'!C13 -> UX | D13: ='체크리스트'!F13 -> 완료 | E13: =IF(TEXT(E$4,"m/d")='체크리스트'!B13,1,"") | F13: =IF(TEXT(F$4,"m/d")='체크리스트'!B13,1,"") -> 1 | G13: =IF(TEXT(G$4,"m/d")='체크리스트'!B13,1,"") | H13: =IF(TEXT(H$4,"m/d")='체크리스트'!B13,1,"") | I13: =IF(TEXT(I$4,"m/d")='체크리스트'!B13,1,"") | J13: =IF(TEXT(J$4,"m/d")='체크리스트'!B13,1,"") | K13: =IF(TEXT(K$4,"m/d")='체크리스트'!B13,1,"") | L13: =IF(TEXT(L$4,"m/d")='체크리스트'!B13,1,"") | M13: =IF(TEXT(M$4,"m/d")='체크리스트'!B13,1,"") | N13: =IF(TEXT(N$4,"m/d")='체크리스트'!B13,1,"")
A14: ='체크리스트'!A14 -> T10 | B14: ='체크리스트'!D14 -> 조건 슬롯 추출 프롬프트 v0 | C14: ='체크리스트'!C14 -> 백엔드 | D14: ='체크리스트'!F14 -> 완료 | E14: =IF(TEXT(E$4,"m/d")='체크리스트'!B14,1,"") | F14: =IF(TEXT(F$4,"m/d")='체크리스트'!B14,1,"") -> 1 | G14: =IF(TEXT(G$4,"m/d")='체크리스트'!B14,1,"") | H14: =IF(TEXT(H$4,"m/d")='체크리스트'!B14,1,"") | I14: =IF(TEXT(I$4,"m/d")='체크리스트'!B14,1,"") | J14: =IF(TEXT(J$4,"m/d")='체크리스트'!B14,1,"") | K14: =IF(TEXT(K$4,"m/d")='체크리스트'!B14,1,"") | L14: =IF(TEXT(L$4,"m/d")='체크리스트'!B14,1,"") | M14: =IF(TEXT(M$4,"m/d")='체크리스트'!B14,1,"") | N14: =IF(TEXT(N$4,"m/d")='체크리스트'!B14,1,"")
A15: ='체크리스트'!A15 -> T11 | B15: ='체크리스트'!D15 -> RAG 벡터 인덱스(FAISS) 초안 구축 | C15: ='체크리스트'!C15 -> 백엔드 | D15: ='체크리스트'!F15 -> 완료 | E15: =IF(TEXT(E$4,"m/d")='체크리스트'!B15,1,"") | F15: =IF(TEXT(F$4,"m/d")='체크리스트'!B15,1,"") -> 1 | G15: =IF(TEXT(G$4,"m/d")='체크리스트'!B15,1,"") | H15: =IF(TEXT(H$4,"m/d")='체크리스트'!B15,1,"") | I15: =IF(TEXT(I$4,"m/d")='체크리스트'!B15,1,"") | J15: =IF(TEXT(J$4,"m/d")='체크리스트'!B15,1,"") | K15: =IF(TEXT(K$4,"m/d")='체크리스트'!B15,1,"") | L15: =IF(TEXT(L$4,"m/d")='체크리스트'!B15,1,"") | M15: =IF(TEXT(M$4,"m/d")='체크리스트'!B15,1,"") | N15: =IF(TEXT(N$4,"m/d")='체크리스트'!B15,1,"")
A16: ='체크리스트'!A16 -> T12 | B16: ='체크리스트'!D16 -> 화면구조(IA) 설계 — 4대 메인화면 6/4/4/8탭 | C16: ='체크리스트'!C16 -> 프론트 | D16: ='체크리스트'!F16 -> 완료 | E16: =IF(TEXT(E$4,"m/d")='체크리스트'!B16,1,"") | F16: =IF(TEXT(F$4,"m/d")='체크리스트'!B16,1,"") -> 1 | G16: =IF(TEXT(G$4,"m/d")='체크리스트'!B16,1,"") | H16: =IF(TEXT(H$4,"m/d")='체크리스트'!B16,1,"") | I16: =IF(TEXT(I$4,"m/d")='체크리스트'!B16,1,"") | J16: =IF(TEXT(J$4,"m/d")='체크리스트'!B16,1,"") | K16: =IF(TEXT(K$4,"m/d")='체크리스트'!B16,1,"") | L16: =IF(TEXT(L$4,"m/d")='체크리스트'!B16,1,"") | M16: =IF(TEXT(M$4,"m/d")='체크리스트'!B16,1,"") | N16: =IF(TEXT(N$4,"m/d")='체크리스트'!B16,1,"")
... A48: ='체크리스트'!A48 -> T44 | B48: ='체크리스트'!D48 -> 최종 리허설 → 발표 | C48: ='체크리스트'!C48 -> 전원 | D48: ='체크리스트'!F48 -> 대기 | E48: =IF(TEXT(E$4,"m/d")='체크리스트'!B48,1,"") | F48: =IF(TEXT(F$4,"m/d")='체크리스트'!B48,1,"") | G48: =IF(TEXT(G$4,"m/d")='체크리스트'!B48,1,"") | H48: =IF(TEXT(H$4,"m/d")='체크리스트'!B48,1,"") | I48: =IF(TEXT(I$4,"m/d")='체크리스트'!B48,1,"") | J48: =IF(TEXT(J$4,"m/d")='체크리스트'!B48,1,"") | K48: =IF(TEXT(K$4,"m/d")='체크리스트'!B48,1,"") | L48: =IF(TEXT(L$4,"m/d")='체크리스트'!B48,1,"") | M48: =IF(TEXT(M$4,"m/d")='체크리스트'!B48,1,"") | N48: =IF(TEXT(N$4,"m/d")='체크리스트'!B48,1,"") -> 1
